Workbook

Sheet Summary
A1: Module | B1: Allocated by | C1: Status | D1: Sheet | E1: Total Test Cases | F1: High Priority | G1: Medium Priority | H1: Low Priority | I1: Automation Candidates (Y) | J1: Total test cases executed | K1: Total test cases Passed | L1: Total test cases Failed | M1: Execution %
A2: Home Page | B2: Sakthi Balaji | C2: Completed | D2: HP - Home Page | E2: =COUNTA('HP - Home Page'!A2:A11) -> 10 | F2: =COUNTIF('HP - Home Page'!I2:I11,"High") -> 5 | G2: =COUNTIF('HP - Home Page'!I2:I11,"Medium") -> 5 | H2: =COUNTIF('HP - Home Page'!I2:I11,"Low") -> 0 | I2: =COUNTIF('HP - Home Page'!L2:L11,"Y") -> 5 | J2: =COUNTA('HP - Home Page'!F2:F11) -> 10 | K2: 9 | L2: 1 | M2: =IF(E2=0,0,J2/E2*100) -> 100
A3: About Us | B3: Siva sri | C3: Completed | D3: AU - About Us | E3: 18 | F3: =COUNTIF('AU - About Us'!I2:I11,"High") -> 4 | G3: =COUNTIF('AU - About Us'!I2:I11,"Medium") -> 5 | H3: =COUNTIF('AU - About Us'!I2:I11,"Low") -> 1 | I3: =COUNTIF('AU - About Us'!L2:L11,"Y") -> 5 | J3: 14 | K3: 11 | L3: 3 | M3: =IF(E3=0,0,J3/E3*100) -> 77.777778
A4: Reports & Accounts | B4: Thiru vikraman | C4: Completed | D4: RA - Reports & Accounts | E4: 21 | F4: =COUNTIF('RA - Reports & Accounts'!I2:I19,"High") -> 9 | G4: =COUNTIF('RA - Reports & Accounts'!I2:I19,"Medium") -> 9 | H4: =COUNTIF('RA - Reports & Accounts'!I2:I19,"Low") -> 0 | I4: =COUNTIF('RA - Reports & Accounts'!L2:L19,"Y") -> 14 | J4: 21 | K4: 9 | L4: 12 | M4: =IF(E4=0,0,J4/E4*100) -> 100
A5: Our Presence | B5: Saraswathi | C5: Completed | D5: OP - Our Presence | E5: =COUNTA('OP - Our Presence'!A2:A11) -> 10 | F5: =COUNTIF('OP - Our Presence'!I2:I11,"High") -> 2 | G5: =COUNTIF('OP - Our Presence'!I2:I11,"Medium") -> 7 | H5: =COUNTIF('OP - Our Presence'!I2:I11,"Low") -> 1 | I5: =COUNTIF('OP - Our Presence'!L2:L11,"Y") -> 4 | J5: =COUNTA('OP - Our Presence'!F2:F11) -> 10 | K5: 9 | L5: 1 | M5: =IF(E5=0,0,J5/E5*100) -> 100
A6: Careers & Engagement | B6: Siva sri | C6: Completed | D6: CE - Careers & Engagement | E6: =COUNTA('CE - Careers & Engagement'!A2:A9) -> 8 | F6: =COUNTIF('CE - Careers & Engagement'!I2:I9,"High") -> 1 | G6: =COUNTIF('CE - Careers & Engagement'!I2:I9,"Medium") -> 6 | H6: =COUNTIF('CE - Careers & Engagement'!I2:I9,"Low") -> 1 | I6: =COUNTIF('CE - Careers & Engagement'!L2:L9,"Y") -> 3 | J6: =COUNTA('CE - Careers & Engagement'!F2:F9) -> 8 | K6: 6 | L6: 2 | M6: =IF(E6=0,0,J6/E6*100) -> 100
A7: Resources & Library | B7: Hannah | C7: Completed | D7: RL - Resources & Library | E7: =COUNTA('RL - Resources & Library'!A2:A9) -> 8 | F7: =COUNTIF('RL - Resources & Library'!I2:I9,"High") -> 2 | G7: =COUNTIF('RL - Resources & Library'!I2:I9,"Medium") -> 4 | H7: =COUNTIF('RL - Resources & Library'!I2:I9,"Low") -> 2 | I7: =COUNTIF('RL - Resources & Library'!L2:L9,"Y") -> 4 | J7: =COUNTA('RL - Resources & Library'!F2:F9) -> 8 | K7: 1 | L7: 7 | M7: =IF(E7=0,0,J7/E7*100) -> 100
A8: State Subsites | B8: Saraswathi | C8: Completed | D8: SS - State Subsites | E8: =COUNTA('SS - State Subsites'!A2:A13) -> 12 | F8: =COUNTIF('SS - State Subsites'!I2:I13,"High") -> 5 | G8: =COUNTIF('SS - State Subsites'!I2:I13,"Medium") -> 7 | H8: =COUNTIF('SS - State Subsites'!I2:I13,"Low") -> 0 | I8: =COUNTIF('SS - State Subsites'!L2:L13,"Y") -> 4 | J8: =COUNTA('SS - State Subsites'!F2:F13) -> 12 | K8: 10 | L8: 2 | M8: =IF(E8=0,0,J8/E8*100) -> 100
A9: Contact Us | B9: gousalya | C9: Completed | D9: CT - Contact | E9: 11 | F9: 5 | G9: 4 | H9: 2 | I9: =COUNTIF('CT - Contact'!L2:L12,"Y") -> 5 | J9: 11 | K9: 1 | L9: 10 | M9: =IF(E9=0,0,J9/E9*100) -> 100
A10: News & events | B10: gousalya | C10: Completed | D10: NM - News & Media | E10: 11 | F10: 5 | G10: 4 | H10: 2 | I10: =COUNTIF('NM - News & Media'!L2:L12,"Y") -> 7 | J10: 8 | K10: 7 | L10: 1 | M10: =IF(E10=0,0,J10/E10*100) -> 72.727273
A11: Global relations | B11: Hannah | C11: Completed | D11: GR - Global Relations | E11: 10 | F11: 4 | G11: 3 | H11: 3 | I11: =COUNTIF('GR - Global Relations'!L2:L11,"Y") -> 5 | J11: 10 | K11: 2 | L11: 8 | M11: =IF(E11=0,0,J11/E11*100) -> 100
A12: UI-UX & Shared Components | B12: Hannah | D12: UX - UI-UX & Shared Components | E12: =COUNTA('UX - UI-UX & Shared Components'!A2:A15) -> 14 | F12: =COUNTIF('UX - UI-UX & Shared Components'!I2:I15,"High") -> 6 | G12: =COUNTIF('UX - UI-UX & Shared Components'!I2:I15,"Medium") -> 7 | H12: =COUNTIF('UX - UI-UX & Shared Components'!I2:I15,"Low") -> 1 | I12: =COUNTIF('UX - UI-UX & Shared Components'!L2:L15,"Y") -> 3 | J12: =COUNTA('UX - UI-UX & Shared Components'!F2:F15) -> 14 | K12: 0 | L12: 0 | M12: =IF(E12=0,0,J12/E12*100) -> 100
A13: Bilingual (i18n) | D13: BL - Bilingual (i18n) | E13: =COUNTA('BL - Bilingual (i18n)'!A2:A11) -> 10 | F13: =COUNTIF('BL - Bilingual (i18n)'!I2:I11,"High") -> 5 | G13: =COUNTIF('BL - Bilingual (i18n)'!I2:I11,"Medium") -> 3 | H13: =COUNTIF('BL - Bilingual (i18n)'!I2:I11,"Low") -> 2 | I13: =COUNTIF('BL - Bilingual (i18n)'!L2:L11,"Y") -> 1 | J13: =COUNTA('BL - Bilingual (i18n)'!F2:F11) -> 10 | K13: 0 | L13: 0 | M13: =IF(E13=0,0,J13/E13*100) -> 100
A14: Admin - Authentication | B14: Sakthi Balaji | C14: Completed | D14: AA - Admin - Authentication | E14: =COUNTA('AA - Admin - Authentication'!A2:A10) -> 9 | F14: =COUNTIF('AA - Admin - Authentication'!I2:I10,"High") -> 5 | G14: =COUNTIF('AA - Admin - Authentication'!I2:I10,"Medium") -> 4 | H14: =COUNTIF('AA - Admin - Authentication'!I2:I10,"Low") -> 0 | I14: =COUNTIF('AA - Admin - Authentication'!L2:L10,"Y") -> 4 | J14: =COUNTA('AA - Admin - Authentication'!F2:F10) -> 9 | K14: 8 | L14: 1 | M14: =IF(E14=0,0,J14/E14*100) -> 100
A15: Admin - Dashboard | B15: No need | D15: AD - Admin - Dashboard | E15: =COUNTA('AD - Admin - Dashboard'!A2:A14) -> 13 | F15: =COUNTIF('AD - Admin - Dashboard'!I2:I14,"High") -> 5 | G15: =COUNTIF('AD - Admin - Dashboard'!I2:I14,"Medium") -> 5 | H15: =COUNTIF('AD - Admin - Dashboard'!I2:I14,"Low") -> 3 | I15: =COUNTIF('AD - Admin - Dashboard'!L2:L14,"Y") -> 2 | J15: =COUNTA('AD - Admin - Dashboard'!F2:F14) -> 13 | K15: 0 | L15: 0 | M15: =IF(E15=0,0,J15/E15*100) -> 100
A16: Admin - CRUD Modules | B16: Saraswathi & sivasri | C16: Completed | D16: AC - Admin - CRUD Modules | E16: =COUNTA('AC - Admin - CRUD Modules'!A2:A16) -> 15 | F16: =COUNTIF('AC - Admin - CRUD Modules'!I2:I16,"High") -> 8 | G16: =COUNTIF('AC - Admin - CRUD Modules'!I2:I16,"Medium") -> 7 | H16: =COUNTIF('AC - Admin - CRUD Modules'!I2:I16,"Low") -> 0 | I16: =COUNTIF('AC - Admin - CRUD Modules'!L2:L16,"Y") -> 7 | J16: =COUNTA('AC - Admin - CRUD Modules'!F2:F16) -> 15 | K16: 3 | L16: 12 | M16: =IF(E16=0,0,J16/E16*100) -> 100
A17: Admin - File Upload | B17: Hannah | C17: Completed | D17: AF - Admin - File Upload | E17: =COUNTA('AF - Admin - File Upload'!A2:A11) -> 10 | F17: =COUNTIF('AF - Admin - File Upload'!I2:I11,"High") -> 4 | G17: =COUNTIF('AF - Admin - File Upload'!I2:I11,"Medium") -> 4 | H17: =COUNTIF('AF - Admin - File Upload'!I2:I11,"Low") -> 2 | I17: =COUNTIF('AF - Admin - File Upload'!L2:L11,"Y") -> 3 | J17: =COUNTA('AF - Admin - File Upload'!F2:F11) -> 10 | K17: 9 | L17: 1 | M17: =IF(E17=0,0,J17/E17*100) -> 100
A18: Admin - Audit Log | B18: Sakthi Balaji | C18: Completed | D18: AL - Admin - Audit Log | E18: =COUNTA('AL - Admin - Audit Log'!A2:A9) -> 8 | F18: =COUNTIF('AL - Admin - Audit Log'!I2:I9,"High") -> 3 | G18: =COUNTIF('AL - Admin - Audit Log'!I2:I9,"Medium") -> 3 | H18: =COUNTIF('AL - Admin - Audit Log'!I2:I9,"Low") -> 2 | I18: =COUNTIF('AL - Admin - Audit Log'!L2:L9,"Y") -> 4 | J18: =COUNTA('AL - Admin - Audit Log'!F2:F9) -> 8 | K18: 7 | L18: 1 | M18: =IF(E18=0,0,J18/E18*100) -> 100
A19: Figma Design Parity | D19: FP - Figma Design Parity | E19: =COUNTA('FP - Figma Design Parity'!A2:A22) -> 21 | F19: =COUNTIF('FP - Figma Design Parity'!I2:I22,"High") -> 5 | G19: =COUNTIF('FP - Figma Design Parity'!I2:I22,"Medium") -> 15 | H19: =COUNTIF('FP - Figma Design Parity'!I2:I22,"Low") -> 1 | I19: =COUNTIF('FP - Figma Design Parity'!L2:L22,"Y") -> 4 | J19: =COUNTA('FP - Figma Design Parity'!F2:F22) -> 21 | K19: 0 | L19: 0 | M19: =IF(E19=0,0,J19/E19*100) -> 100
A20: API Testing | D20: API - API Testing | E20: =COUNTA('API - API Testing'!A2:A21) -> 20 | F20: =COUNTIF('API - API Testing'!I2:I21,"High") -> 8 | G20: =COUNTIF('API - API Testing'!I2:I21,"Medium") -> 11 | H20: =COUNTIF('API - API Testing'!I2:I21,"Low") -> 1 | I20: =COUNTIF('API - API Testing'!L2:L21,"Y") -> 20 | J20: =COUNTA('API - API Testing'!F2:F21) -> 20 | K20: 0 | L20: 0 | M20: =IF(E20=0,0,J20/E20*100) -> 100
A21: Non-Functional | B21: Sakthi Balaji | C21: Completed | D21: NF - Non-Functional | E21: =COUNTA('NF - Non-Functional'!A2:A17) -> 16 | F21: =COUNTIF('NF - Non-Functional'!I2:I17,"High") -> 6 | G21: =COUNTIF('NF - Non-Functional'!I2:I17,"Medium") -> 9 | H21: =COUNTIF('NF - Non-Functional'!I2:I17,"Low") -> 1 | I21: =COUNTIF('NF - Non-Functional'!L2:L17,"Y") -> 4 | J21: =COUNTA('NF - Non-Functional'!F2:F17) -> 16 | K21: 0 | L21: 0 | M21: =IF(E21=0,0,J21/E21*100) -> 100
A22: Office Subsites | B22: Saraswathi | C22: Completed | D22: OS - Office Subsites | E22: =COUNTA('[1]OS - Office Subsites'!A2:A13) -> 12 | F22: =COUNTIF('[1]OS - Office Subsites'!I2:I13,"High") -> #VALUE! | G22: =COUNTIF('[1]OS - Office Subsites'!I2:I13,"Medium") -> #VALUE! | H22: =COUNTIF('[1]OS - Office Subsites'!I2:I13,"Low") -> #VALUE! | I22: =COUNTIF('[1]OS - Office Subsites'!L2:L13,"Y") -> #VALUE! | J22: 12 | K22: 7 | L22: 5 | M22: =IF(E22=0,0,J22/E22*100) -> 100
A23: Defence Subsite | B23: Saraswathi & sivasri | C23: in progress | D23: DS - Defence Subsite | E23: =COUNTA('[1]DS - Defence Subsite'!A2:A17) -> 16 | F23: =COUNTIF('[1]DS - Defence Subsite'!I2:I17,"High") -> #VALUE! | G23: =COUNTIF('[1]DS - Defence Subsite'!I2:I17,"Medium") -> #VALUE! | H23: =COUNTIF('[1]DS - Defence Subsite'!I2:I17,"Low") -> #VALUE! | I23: =COUNTIF('[1]DS - Defence Subsite'!L2:L17,"Y") -> #VALUE! | J23: =COUNTA('[1]DS - Defence Subsite'!F2:F17) -> 0 | K23: 0 | L23: 0 | M23: =IF(E23=0,0,J23/E23*100) -> 0
A24: Training Institute Subsites | B24: Siva sri | C24: Completed | D24: TI - Training Institutes | E24: =COUNTA('[1]TI - Training Institutes'!A2:A10) -> 9 | F24: =COUNTIF('[1]TI - Training Institutes'!I2:I10,"High") -> #VALUE! | G24: =COUNTIF('[1]TI - Training Institutes'!I2:I10,"Medium") -> #VALUE! | H24: =COUNTIF('[1]TI - Training Institutes'!I2:I10,"Low") -> #VALUE! | I24: =COUNTIF('[1]TI - Training Institutes'!L2:L10,"Y") -> #VALUE! | J24: 9 | K24: 1 | L24: 8 | M24: =IF(E24=0,0,J24/E24*100) -> 100
A25: Admin - New Sections | B25: gousalya | C25: in progress | D25: AN - Admin - New Sections | E25: =COUNTA('[1]AN - Admin - New Sections'!A2:A35) -> 34 | F25: =COUNTIF('[1]AN - Admin - New Sections'!I2:I35,"High") -> #VALUE! | G25: =COUNTIF('[1]AN - Admin - New Sections'!I2:I35,"Medium") -> #VALUE! | H25: =COUNTIF('[1]AN - Admin - New Sections'!I2:I35,"Low") -> #VALUE! | I25: =COUNTIF('[1]AN - Admin - New Sections'!L2:L35,"Y") -> #VALUE! | J25: 34 | K25: 10 | L25: 0 | M25: =IF(E25=0,0,J25/E25*100) -> 100
A26: Super Admin | B26: All | C26: Completed | D26: SA-Super Admin | E26: 301 | F26: 0 | G26: 0 | H26: 0 | I26: 0 | J26: 301 | K26: 192 | L26: 54
A27: TOTAL | E27: =SUM(E2:E26) -> 627 | F27: =SUM(F2:F21) -> 97 | G27: =SUM(G2:G21) -> 122 | H27: =SUM(H2:H21) -> 25 | I27: =SUM(I2:I21) -> 108 | J27: =SUM(J2:J26) -> 604 | K27: =SUM(K2:K21) -> 92 | L27: =SUM(L2:L21) -> 62 | M27: =IF(SUM(E2:E21)=0,0,SUM(J2:J21)/SUM(E2:E21)*100) -> 97.254902
A30: Defect Status | B30: No. of Defects
A31: Open | B31: 30
A32: Closed | B32: 22
A33: Ready to Retest | B33: 0
A34: Accepted | B34: 15
A35: Total Defects | B35: 67
A38: Priority Wise Defects | B38: Priority Wise Defects Counts
A39: High | B39: 30
A40: Closed + high | B40: 7
A41: Open + high | B41: 23
A42: Medium | B42: 32
A43: Low | B43: 9

Sheet Defect_summary 
A1: Defect No | B1: Module Name | C1: Defect Summary | D1: URL's | E1: Defect description | F1: Defect Status | G1: Developer Comments | H1: developer status | I1: Priority | J1: Environment | K1: Assigned To dev owner | L1: Tested by | M1: Root cause | N1: Defect creation date | O1: Defect target date | P1: Comments | Q1: Developed By | R1: Screenshot | S1: Defect Status | T1: Defect closed date
A2: D-01 | B2: About Us | C2: PDF download redirects to the main CAG website and displays a 404 error. | D2: http://13.202.245.81:3001/About/About-Us/Audit-Regulation https://cag.gov.in/uploads/media/Regulations-on-Audit-and-Accounts-2020-Gazette-60b73c4d7d91e8-78235251.pdf | E2: No documents are available under Constitutional Provisions and Duties & Powers Act on the new website. Under Audit Regulations, clicking View PDF displays a download option, but clicking Download redirects to cag.gov.in and displays a 404 Not Found | F2: OPEN | G2: closed | I2: High | J2: http://13.202.245.81:3001/ | L2: Sivasri | N2: 24/10/2026 | R2: #VALUE!
A3: D-02 | B3: About Us | C3: First two officers' details are not displaying in the Organisation Chart. | D3: http://13.202.245.81:3001/About/About-Us/Organisation-Chart | E3: When clicking on the first two officers in the Organisation Chart, the details popup opens, but the email, contact number, and reporting officer information are not displaying. | F3: OPEN | G3: second officer details are visible and first officer contact and email not in live site | I3: Medium | J3: http://13.202.245.81:3001/ | L3: Sivasri | N3: 24/10/2026 | R3: #VALUE!
A4: D-03 | B4: About Us | C4: Hindi translation is incomplete; English text is displayed on the Duties & Powers Act and Constitutional Provisions pages. | D4: http://13.202.245.81:3001/About/About-Us/Duties-&-Powers-Act http://13.202.245.81:3001/About/About-Us/Constitutional-Provisions | E4: Hindi translation is incomplete on the Duties & Powers Act and Constitutional Provisions pages; some parts of the content continue to show in English after toggling the language to Hindi. | F4: OPEN | G4: closed | I4: Medium | J4: http://13.202.245.81:3001/ | L4: Sivasri | N4: 24-10-2026 | R4: #VALUE!
A5: D-04 | B5: Careers & Engagement | C5: PDF file names are not translated when switching languages in the Careers & Engagement section. | D5: http://13.202.245.81:3001/Career-Engagement/Tenders-and-Contracts | E5: In all submodules under Careers & Engagement, when switching the language from English to Hindi, the PDF file names are still displayed in English instead of Hindi. | F5: OPEN | G5: closed | I5: Medium | J5: http://13.202.245.81:3001/ | L5: Sivasri | N5: 24-10-2026 | R5: #VALUE!
A6: D-05 | B6: Careers & Engagement | C6: View PDF functionality is not working in multiple submodules under Careers & Engagement. | D6: http://13.http://13.202.245.81:3001/Career-Engagement/Empanelment-of-Retired-Officers http://13.202.245.81:3001/Career-Engagement/CA-Empanelment http://13.202.245.81:3001/Career-Engagement/Research-Associates | E6: The View PDF option is not working in the following submodules: Careers & Engagement → Learning & Opportunities → Research Associates Careers & Engagement → Engagement & Empanelment → CA Empanelment Careers & Engagement → Engagement & Empanelment → Empanelment of Retired Officers as Inquiry Officers | F6: OPEN | G6: closed | I6: Medium | J6: http://13.202.245.81:3001/ | L6: Sivasri | N6: 24-10-2028 | R6: #VALUE!
A7: D-06 | B7: Home Page | C7: Homepage content is not fully translated into Hindi. Some sections/text remain in English after switching to Hindi. | D7: http://13.202.245.81:3000/ | E7: Upon switching the homepage language to Hindi, some homepage content remains displayed in English instead of being fully translated into Hindi. | F7: OPEN | G7: closed | I7: Medium | J7: http://13.202.245.81:3001/ | L7: Sakthi | N7: 25-09-2026 | S7: Closed | T7: 21-10-2026
A8: D-07 | B8: Home Page | C8: Broken links or assets are found on the homepage | D8: http://13.202.245.81:3000/ | E8: While validating the homepage, broken links or assets were identified. Some visible links/resources are returning errors and are not functioning as expected. | F8: OPEN | G8: closed | I8: Medium | J8: http://13.202.245.81:3001/ | L8: Sakthi | N8: 25-09-2026 | P8: #VALUE! | S8: Closed | T8: 21-10-2026
A9: D-08 | B9: Reports | C9: Report Download button opens the PDF in the browser instead of downloading the file | D9: http://13.202.245.81:3000/Reports | E9: When the Download button is clicked for a report with an attached PDF, the PDF is rendered/opened in the browser instead of being downloaded as a file. The expected download functionality is not working. | F9: OPEN | G9: closed | I9: Medium | J9: http://13.202.245.81:3001/ | L9: Sakthi | N9: 25-09-2026
A10: D-09 | B10: Admin-Authentication | C10: Invalid password is not rejected during admin login | D10: http://13.202.245.81:3000/admin/login | E10: When a valid username is entered with an incorrect password, the system does not reject the login attempt as expected and does not display an appropriate invalid-credentials error message. | F10: OPEN | G10: closed | I10: Medium | J10: http://13.202.245.81:3001/ | L10: Sakthi | N10: 25-09-2026
A11: D-10 | B11: Resource and Library | C11: Resource and library ---> Tenders subsite | D11: http://13.202.245.81:3000/Resources | E11: The subsite does not even exists on the site | F11: OPEN | G11: same in live | I11: MEDIUM | J11: http://13.202.245.81:3001/ | L11: HANNAH | N11: 25-09-2026 | R11: Picture
A12: D-11 | B12: Resource and Library | C12: Resource and library ---> Circulars subsite | D12: http://13.202.245.81:3000/Resources | E12: The subpage does not even exists on the site | F12: OPEN | G12: same in live | I12: MEDIUM | J12: http://13.202.245.81:3001/ | L12: HANNAH | N12: 25-09-2026 | R12: #VALUE!
A13: D-12 | B13: Resource and Library | C13: Resource and library ---> Search Bar | D13: http://13.202.245.81:3000/Resources | E13: The search bar does not show the matching documents when searched the page remains the same | F13: OPEN | G13: closed | I13: LOW | J13: http://13.202.245.81:3001/ | L13: HANNAH | N13: 25-09-2026 | R13: #VALUE! | S13: Closed | T13: 21-10-2026
A14: D-13 | B14: Resource and Library | C14: Resource and library ---> Bilingual Content | D14: http://13.202.245.81:3000/Resources | E14: The document titles are not in Hindi | F14: OPEN | G14: closed | I14: MEDIUM | J14: http://13.202.245.81:3001/ | L14: HANNAH | N14: 25-09-2026 | R14: #VALUE!
A15: D-14 | B15: Resource and Library | C15: Resource and library ---> Empty Category State | D15: http://13.202.245.81:3000/Resources | E15: There is no empty category on the page | F15: OPEN | G15: same in live | I15: LOW | J15: http://13.202.245.81:3001/ | L15: HANNAH | N15: 25-09-2026 | R15: #VALUE!
A16: D-15 | B16: Our Presence | C16: Incorrect state name ("Chandigarh") displayed instead of "Punjab" | D16: http://13.202.245.81:3001/Our-Presence/Index-Menu/Central-Audit-Offices?filter=defence | E16: In the Defence Audit Offices section, the state header is incorrectly displayed as "Chandigarh" instead of "Punjab". Please update the label to Punjab. | F16: open | G16: closed | I16: Medium | J16: http://13.202.245.81:3001/ | L16: Saraswathi | R16: #VALUE!
A17: D-16 | B17: Our Presence | C17: Office names and text content mismatch between Figma design and Live site | D17: http://13.202.245.81:3001/Our-Presence/Index-Menu/Central-Audit-Offices?filter=railway | E17: 1. West Bengal: Live site displays 3 office names (Eastern Railway, South Eastern Railway, Railway Production Units & Metro), whereas Figma design specifies Railway, Kolkata, DO-1 and Railway, Kolkata, DO-2. 2. Uttar Pradesh: Office name ordering is swapped compared to Figma specs. 3. URL Routing Names: Hovering/clicking on entries shows non-standard URL path names (e.g., /rly/hubli/en instead of standard menu routing). | F17: open | G17: closed | I17: High | J17: http://13.202.245.81:3001/ | L17: Saraswathi | R17: #VALUE!
A18: D-17 | B18: Our Presence | C18: Incorrect categorization: "Defence - Commercial, Bengaluru" listed under Other Ministries section | D18: http://13.202.245.81:3001/Our-Presence/Index-Menu/Central-Audit-Offices?filter=other | E18: Under Other Ministries Audit Offices, for the Karnataka state card, "Defence - Commercial, Bengaluru" is wrongly displayed. Since Defence has its own dedicated menu ("Defence" tab), this item should either be moved to the Defence section or renamed/removed from Other Ministries. | F18: open | G18: closed | I18: High | J18: http://13.202.245.81:3001/ | L18: Saraswathi | R18: #VALUE!
A19: D-18 | B19: State subsites | C19: PDF documents are missing/not displaying under the Document column | D19: http://13.202.245.81:3001/ae/andhra-pradesh/en/state-accounts-report?defuat_account_report_type=357 | E19: On navigating to Annual Accounts > Account at Glance, the records are listed in the table, but the Document column shows a hyphen (-) instead of downloadable PDF files/links for all financial years. | F19: open | G19: closed | I19: High | J19: http://13.202.245.81:3001/ | L19: Saraswathi | R19: #VALUE!
A20: D-19 | B20: State subsites | C20: PDF documents are missing/not displaying under the Document column | D20: http://13.202.245.81:3001/ae/arunachal-pradesh/en/page-ae-arunachal-pradesh-page-agae-itanagar-accountsataglancw | E20: On navigating to Annual Accounts > Appropriation Accounts, the records are listed in the table, but the Document column shows a hyphen (-) instead of downloadable PDF files/links for all financial years. | F20: open | G20: closed | I20: High | J20: http://13.202.245.81:3001/
A21: D-20 | B21: State subsites | C21: PDF documents are missing/not displaying under the Document column | D21: http://13.202.245.81:3001/ae/andhra-pradesh/en/state-accounts-report?defuat_account_report_type=360 | E21: On navigating to Monthly Accounts> Monthly Key Editor, the records are listed in the table, but the Document column shows a hyphen (-) instead of downloadable PDF files/links for all financial years. | F21: open | G21: closed | I21: High | J21: http://13.202.245.81:3001/
A22: D-21 | B22: Resource and Library | C22: Resources document lists don’t match Figma and show junk test entries | D22: http://13.202.245.81:3001/Resources/Annual-Report | E22: Resources category pages (e.g. Recruitment Policy, Annual Report) show dummy entries. Documents show no date, group or file size, and the Archive button, Search by title bar and category filter from Figma are missing. The Recruitment Policy page banner and breadcrumb say “Recruitment Rules” instead of “Recruitment Policy”. | F22: Open | G22: closed | I22: Medium | J22: http://13.202.245.81:3001/ | L22: HANNAH | N22: 24-10-2026 | R22: #VALUE!
A23: D-22 | B23: Resource and Library | C23: PDF documents fail to open: file storage domain not reachable | D23: http://13.202.245.81:3001/Resources/Annual-Report | E23: Clicking “View PDF” on any Resources document (e.g. Annual Report 2024-25, Manuals) gives “This site can’t be reached”. All files point to d7i5wg8xwe4hf.cloudfront.net, which doesn’t exist. This is a site-wide issue. | F23: OPEN | G23: closed | I23: Medium | J23: http://13.202.245.81:3001/ | L23: HANNAH | N23: 24-10-2026 | R23: #VALUE!
A24: D-23 | B24: Resource and Library | C24: Tenders sub-page not available under Resources | D24: http://13.202.245.81:3001/Resources/Annual-Report | E24: There is no Tenders page in the Resources menu, sidebar or site search, so tender entries can’t be verified. It’s also missing from the Figma Resources menu; scope needs confirmation. | F24: OPEN | G24: same in live | I24: Medium | J24: http://13.202.245.81:3001/ | L24: HANNAH | N24: 24-10-2026 | R24: #VALUE!
A25: D-24 | B25: Resource and Library | C25: Circulars sub-page not available under Resources | D25: http://13.202.245.81:3001/Resources/Annual-Report | E25: There is no Circulars / Departmental Circulars page in the Resources menu, sidebar or site search, so circular entries can’t be verified. It’s also missing from the Figma Resources menu; scope needs confirmation. | F25: OPEN | G25: same in live | I25: Medium | J25: http://13.202.245.81:3001/ | L25: HANNAH | N25: 24-10-2026 | R25: #VALUE!
A26: D-25 | B26: Resource and Library | C26: Search doesn’t return matching Resources documents | D26: http://13.202.245.81:3001/Reports?query=2024 | E26: Searching “2024” redirects to /Reports?query=2024 and returns 202 unrelated results (2025/2026 reports). Resources documents aren’t searched, and Resources pages lack the “Search by title” bar shown in Figma. | F26: OPEN | G26: closed | I26: Low | J26: http://13.202.245.81:3001/ | L26: HANNAH | N26: 24-10-2026 | R26: #VALUE!
A27: D-26 | B27: Resource and Library | C27: Document titles not translated in Hindi | D27: http://13.202.245.81:3001/Resources/Annual-Report | E27: After switching the language to Hindi on Resources → Annual Report, the menu, sidebar, breadcrumb, banner and buttons translate correctly, but document titles (e.g. “Annual Report 2024-25”) stay in English. | F27: OPEN | G27: closed | I27: Medium | J27: http://13.202.245.81:3001/ | L27: HANNAH | N27: 24-10-2026 | R27: #VALUE!
A28: D-27 | B28: Resource and Library | C28: Empty category state not testable on Resources | D28: http://13.202.245.81:3000/Resources | E28: No Resources category with zero documents exists on the live site, so the empty-state message for RL-08 could not be checked. The only empty-state message found is “No reports matching current search filters” on the Reports search page. | F28: Open | G28: closed | I28: Medium | J28: http://13.202.245.81:3001/ | L28: HANNAH | N28: 26-10-2026 | R28: #VALUE!
A29: D-28 | B29: Global Relations | C29: Global Relations pages don’t match Figma formatting | D29: : http://13.202.245.81:3001/About/Index-Menu-About/Global-relations/Association%20with%20INTOSAI and http://13.202.245.81:3001/About/Index-Menu-About/Global-relations/Multilateral%20Engagement | E29: Lists have no bullets, paragraphs have no spacing, font sizes are inconsistent and URLs aren’t styled as links. The mega menu is missing the Training Institutes and Contact columns. | F29: OPEN | G29: closed | I29: High | J29: http://13.202.245.81:3001/ | L29: HANNAH | N29: 24-10-2026 | R29: #VALUE!
A30: D-29 | B30: Global Relations | C30: Broken links on Global Relations pages | D30: http://13.202.245.81:3001/About/Index-Menu-About/Global-relations/Association%20with%20ASOSAI and http://13.202.245.81:3001/en/photo-gallery/view/56th-Governing-Board-Meeting-15th-ASOSAI-Assembly-and-57th-Governing-Board… | E30: The INTOSAI PFAC link doesn’t load, all ASOSAI speech PDFs fail (CloudFront domain not found), and the ASOSAI image links redirects to 404. | F30: OPEN | G30: intosai pfac is an external link, asosai all r working | I30: Low | J30: http://13.202.245.81:3001/ | L30: HANNAH | N30: 24-10-2026 | R30: #VALUE!
A31: D-30 | B31: Global Relations | C31: Global Relations admin list is missing the Website filter and Language | D31: http://13.202.245.81:3001/admin/global-relations?tab=international-bodies | E31: The admin list only has Domain and Status filters, and no Language column is shown. Sort By and Rows per page controls were also not visible. | F31: OPEN | I31: High | J31: http://13.202.245.81:3001/ | L31: HANNAH | N31: 26-10-2026 | R31: #VALUE!
A32: D-31 | B32: Global Relations | C32: Global Relations admin has no option to add a new entry | D32: http://13.202.245.81:3001/admin/global-relations?tab=international-bodies | E32: The Add or New button is missing on the International Bodies, Bilateral Relations, Audit Engagements, and Relations Wing tabs, and only Live Editor is available. Entries can only be edited, not created, from the admin panel. | F32: OPEN | I32: High | J32: http://13.202.245.81:3001/ | L32: HANNAH | N32: 26-10-2026 | R32: #VALUE!
A33: D-32 | B33: Reports | C33: Cannot see reports - UI not responsive, also the page navigation below isnt properly visible | D33: Comptroller and Auditor General of India | E33: the third column of the reports cant be viewed in full , UI not responsive | F33: OPEN | G33: closed | I33: High | L33: Vikram | R33: #VALUE!
A34: D-33 | B34: Reports | C34: The caption of images is being rendered on images and is flickkering, | D34: Comptroller and Auditor General of India | E34: captions of images are flickering around reports, also report img is not visible | F34: OPEN | G34: closed | I34: Medium | J34: http://13.202.245.81:3001/ | L34: Vikram | R34: #VALUE!
A35: D-34 | B35: News & Events | C35: Some event images are displayed as static pictures instead of clickable links. | D35: http://13.202.245.81:3001/News-and-Events/events#event-65 | E35: Event images should load correctly, and if they are intended to be clickable, selecting them should navigate to the corresponding event details page. | F35: OPEN | I35: Medium | J35: http://13.202.245.81:3001/ | L35: Sivasri | N35: 26/10/2026 | R35: #VALUE!
A36: D-35 | B36: Global Relations | C36: Global Relations admin has no option to delete an entry. | D36: http://13.202.245.81:3001/admin/global-relations?tab=international-bodies | E36: Each row only shows Live Editor, a view icon, and an external link, with no delete (trash) icon. Entries can’t be removed from the admin panel. | F36: OPEN | I36: Medium | J36: http://13.202.245.81:3001/ | L36: HANNAH | N36: 26-10-2026 | R36: #VALUE!
A37: D-36 | B37: Global Relations | C37: Hindi version of Global Relations page is empty. | D37: http://13.202.245.81:3001/admin/global-relations?tab=international-bodies | E37: When switching Association with INTOSAI to हिन्दी in the Live Editor, the title is blank and the canvas says “Canvas is currently empty.” There is no way to add an entry in both English and Hindi from the admin panel. | F37: OPEN | I37: Medium | J37: http://13.202.245.81:3001/ | L37: HANNAH | N37: 26-10-2026 | R37: #VALUE!
A38: D-37 | B38: Global Relations | C38: Global Relations admin list has no Sort By or Rows per page controls. | D38: http://13.202.245.81:3001/admin/global-relations?tab=international-bodies | E38: The International Bodies list shows no sorting dropdown or rows-per-page selector. The test expects both controls to change the list order and page size. | F38: OPEN | I38: Low | J38: http://13.202.245.81:3001/ | L38: HANNAH | N38: 26-10-2026 | R38: #VALUE!
A39: D-38 | B39: Global Relations | C39: No confirmed defect yet; test is blocked. | D39: http://13.202.245.81:3001/admin/global-relations?tab=international-bodies and http://13.202.245.81:3000/Reports?query=zzzqqq | E39: The admin list correctly shows “No records found” for a search with no matches. We couldn’t create a Global Relations section with zero entries, so the empty state on the public side is still untested. | F39: OPEN | I39: Low | J39: http://13.202.245.81:3001/ | L39: HANNAH | N39: 26-10-2026 | R39: #VALUE!
A40: D-39 | B40: Training Institute | C40: Contrast toggle is missing | D40: http://13.202.245.81:3001/Our-Presence/Index-Menu/Traning-Institutes?filter=regional&center=delhi | E40: Contrast toggle is not available in training institute | F40: OPEN | I40: Medium | J40: http://13.202.245.81:3001/ | L40: Sivasri | N40: 26-10-2026 | R40: #VALUE!
...

Sheet UX - UI-UX & Shared Components
A1: Test Case ID | B1: Module | C1: Feature / Component | D1: Test Scenario | E1: Preconditions | F1: Test Steps | G1: Test Data | H1: Expected Result | I1: Priority | J1: Severity | K1: Test Type | L1: Automation Candidate | M1: Status | N1: Actual Result | O1: Comments
A2: UX-01 | B2: UI-UX & Shared Components | C2: Header Layout (Core) | D2: Verify the redesigned core Header displays all intended elements | E2: Any public page loaded | F2: 1. Load a public page 2. Inspect the Header for logo, main navigation, language toggle and utility links | G2: N/A | H2: Header matches the intended redesign: correct elements, order and styling | I2: High | J2: Medium | K2: UI/UX | L2: N | M2: Executed | N2: PASS | O2: All header elements and menu items are present. The banner image is broken, but it is outside the header
A3: UX-02 | B3: UI-UX & Shared Components | C3: Header Parity (Core vs Addon) | D3: Verify addon/Header.tsx parity with the core Header where the addon variant is used | E3: Confirm which Header variant is active in the build | F3: 1. Identify pages/build using the addon Header 2. Compare visually and functionally to the core Header | G3: N/A | H3: Both variants match, or any intentional differences are documented and approved by design | I3: High | J3: Medium | K3: Regression | L3: N
A4: UX-03 | B4: UI-UX & Shared Components | C4: Main Navigation Order | D4: Verify the 5 main navigation items appear in the correct order with correct sub-menus | E4: Any public page loaded | F4: 1. Inspect the main navigation bar 2. Hover/click each of About Us, Our Presence, Reports, Careers, Resources, Global Relations | G4: site.config.ts mainNavigation order | H4: Items appear in the documented order and each sub-category flyout is correct | I4: High | J4: Medium | K4: Functional | L4: Y | M4: Executed | N4: PASS | O4: Menu shows 6 main modules and all dropdowns open on hover and links open correct pages.
A5: UX-04 | B5: UI-UX & Shared Components | C5: Menu Parity (Core vs Addon) | D5: Verify addon/Menu.tsx enhanced multi-level navigation matches core Menu behaviour | E5: Confirm which Menu variant is active | F5: 1. Open multi-level menu items on pages using each variant 2. Compare open/close behaviour and styling | G5: N/A | H5: Both variants behave consistently, or differences are documented as intentional | I5: Medium | J5: Medium | K5: Regression | L5: N | M5: Executed | N5: PASS | O5: Menu opens on hover, stays open when mouse moves onto it, and closes on mouse leave or click.
A6: UX-05 | B6: UI-UX & Shared Components | C6: Footer Content | D6: Verify Footer displays correct contact details and external links | E6: Any public page loaded | F6: 1. Scroll to Footer 2. Verify address, email, phone and links to INTOSAI, ASOSAI, india.gov.in | G6: site.config.ts contact & externalLinks | H6: All footer details are accurate and external links resolve correctly | I6: Medium | J6: Medium | K6: Functional | L6: Y | M6: Executed | N6: FAIL | O6: Footer has no address, email, phone, or INTOSAI/ASOSAI links; contact details are only on Contact Us page
A7: UX-06 | B7: UI-UX & Shared Components | C7: Footer Parity (Core vs Addon) | D7: Verify addon/Footer.tsx parity with the core Footer | E7: Confirm which Footer variant is active | F7: 1. Compare addon Footer to core Footer visually and functionally | G7: N/A | H7: Both variants match, or differences are documented as intentional | I7: Medium | J7: Low | K7: Regression | L7: N | M7: Executed
A8: UX-07 | B8: UI-UX & Shared Components | C8: Breadcrumb Accuracy | D8: Verify breadcrumb trails are present and accurate on nested pages | E8: On a nested page (e.g., About Us sub-page, Report detail, State Subsite) | F8: 1. Navigate several levels deep 2. Inspect the breadcrumb trail | G8: N/A | H8: Breadcrumb accurately reflects the navigation path on every nested page tested | I8: Medium | J8: Medium | K8: UI/UX | L8: Y | M8: Executed | N8: PASS | O8: Breadcrumb shows the correct path on About Us pages. Checked on CAG of India, Vision, Mission and Core Values, and Organisation Chart.
A9: UX-08 | B9: UI-UX & Shared Components | C9: Breadcrumb Parity (Addon) | D9: Verify addon/Breadcrumb.tsx configurable labels render correctly where used | E9: A page uses the addon Breadcrumb | F9: 1. Load a page using the addon Breadcrumb 2. Verify configured labels display as intended | G9: N/A | H9: Configured labels render correctly and match the core Breadcrumb's accuracy | I9: Low | J9: Low | K9: Regression | L9: N | M9: Executed
A10: UX-09 | B10: UI-UX & Shared Components | C10: Cross-Page Visual Consistency | D10: Verify consistent spacing, typography, colour and iconography across redesigned pages | E10: Multiple redesigned pages available | F10: 1. Compare spacing, font usage, colour palette and Lucide icon usage across Home, Reports, About Us and a State Subsite | G10: N/A | H10: Visual language is consistent across all pages sampled; no stray fonts/colours from the pre-redesign UI | I10: High | J10: Medium | K10: UI/UX | L10: N | M10: Executed | N10: PASS | O10: Fonts, colours, icons and spacing are consistent across Home, About Us, Reports and Resources pages.
A11: UX-10 | B11: UI-UX & Shared Components | C11: Sticky Header Behaviour | D11: Verify header scroll behaviour does not obscure content | E11: A long page (e.g., Reports listing) | F11: 1. Scroll down and up on a long page 2. Observe header behaviour | G11: N/A | H11: Sticky/collapsing header (if implemented) behaves smoothly and never overlaps interactive content | I11: Medium | J11: Low | K11: UI/UX | L11: N | M11: Executed | N11: PASS | O11: Header scrolls away smoothly on the Reports page and does not cover any content.
A12: UX-11 | B12: UI-UX & Shared Components | C12: Mobile Navigation | D12: Verify the mobile hamburger menu opens/closes and exposes all navigation items | E12: Mobile viewport (375x667) | F12: 1. Load any page at mobile width 2. Open the hamburger menu 3. Navigate through all top-level and sub items 4. Close the menu | G12: N/A | H12: All navigation items are reachable on mobile and the menu opens/closes cleanly | I12: High | J12: Medium | K12: UI/UX | L12: N | M12: Executed | N12: PASS | O12: Mobile menu at 375x667 shows all items, sub-menus open on tap, and the menu closes.
A13: UX-12 | B13: UI-UX & Shared Components | C13: Language Toggle Placement | D13: Verify the EN/HI toggle is consistently placed and styled across all Header instances | E13: Multiple pages with different layouts (public, state subsite) | F13: 1. Locate the language toggle on Home, a public page, and a State Subsite 2. Compare position and styling | G13: N/A | H13: Toggle placement and styling are consistent everywhere it appears | I13: Medium | J13: Low | K13: UI/UX | L13: N | M13: Executed
A14: UX-13 | B14: UI-UX & Shared Components | C14: Layout Regression vs Design Reference | D14: Verify redesigned pages match the approved design reference | E14: Approved design mockups available (if supplied) | F14: 1. Compare each redesigned page side-by-side against its design reference 2. Note any deviations | G14: Design mockups (if provided) | H14: No unintended layout drift from the approved design; deviations are flagged for design review | I14: High | J14: Medium | K14: UI/UX | L14: N | M14: Executed
A15: UX-14 | B15: UI-UX & Shared Components | C15: Layout Routing (RootLayoutWrapper) | D15: Verify admin and state-subsite routes correctly skip the public Header/Footer | E15: Access to an admin route and a state subsite route | F15: 1. Navigate to an admin page 2. Navigate to a state subsite page 3. Observe whether the public Header/Footer render or flash briefly | G15: N/A | H15: Admin and state-subsite routes render their own layout shell with no flash of the public Header/Footer | I15: Medium | J15: Medium | K15: Functional | L15: N | M15: Executed

Sheet RA - Reports & Accounts
A1: Test Case ID | B1: Module | C1: Feature / Component | D1: Test Scenario | E1: Preconditions | F1: Test Steps | G1: Test Data | H1: Expected Result | I1: Priority | J1: Severity | K1: Test Type | L1: Automation Candidate | M1: Status | N1: Actual Result | O1: Comments
A2: RA-01 | B2: Reports & Accounts | C2: Reports Listing | D2: Verify Reports page loads the default first page with default sort and page size | E2: Report data seeded | F2: 1. Navigate to Reports page 2. Inspect the first page of results and default sort order | G2: Default pageSize=9, sort=newest | H2: First 9 reports display, sorted newest first, matching /api/reports defaults | I2: High | J2: Medium | K2: Functional | L2: Y | M2: Executed | N2: Failed | O2: Not to the latest on top
A3: RA-02 | B3: Reports & Accounts | C3: Keyword Search | D3: Verify searching by keyword returns only matching reports | E3: Report data seeded | F3: 1. Enter a known keyword in the search box 2. Submit search 3. Inspect results | G3: Keyword present in a known report's title/overview | H3: Only reports containing the keyword in title or overview are returned | I3: High | J3: Medium | K3: Functional | L3: Y | M3: Executed | N3: Pass
A4: RA-03 | B4: Reports & Accounts | C4: Filter by Level | D4: Verify filtering by Government Level returns the correct subset | E4: Report data seeded | F4: 1. Select a Level filter (Union / States / Local Bodies) 2. Inspect results | G4: level=Union | H4: Only reports matching the selected level are returned | I4: High | J4: Medium | K4: Functional | L4: Y | M4: Executed | N4: Pass
A5: RA-04 | B5: Reports & Accounts | C5: Filter by Sector | D5: Verify filtering by Ministry/Sector returns the correct subset | E5: Report data seeded | F5: 1. Select a Sector filter 2. Inspect results | G5: A known sector value | H5: Only reports matching the selected sector are returned | I5: Medium | J5: Medium | K5: Functional | L5: Y | M5: Executed | N5: Pass
A6: RA-05 | B6: Reports & Accounts | C6: Filter by Report Type | D6: Verify filtering by report type returns the correct subset | E6: Report data seeded | F6: 1. Select a report type (Compliance/Financial/Performance/ADC) 2. Inspect results | G6: type=Performance | H6: Only reports of the selected type are returned | I6: Medium | J6: Medium | K6: Functional | L6: Y | M6: Executed | N6: Pass
A7: RA-06 | B7: Reports & Accounts | C7: Filter by Year | D7: Verify filtering by year returns the correct subset | E7: Report data seeded | F7: 1. Select a report year 2. Inspect results | G7: A known year value | H7: Only reports published in the selected year are returned | I7: Medium | J7: Medium | K7: Functional | L7: Y | M7: Executed | N7: Failed | O7: Filter by year - reports are showing 2026 data for 2024 filter
A8: RA-07 | B8: Reports & Accounts | C8: Filter by State | D8: Verify filtering by state returns the correct subset | E8: Report data seeded | F8: 1. Select a state filter 2. Inspect results | G8: state_id of a known state | H8: Only reports tagged to the selected state are returned | I8: Medium | J8: Medium | K8: Functional | L8: Y | M8: Executed | N8: Failed | O8: No clear segregation on how the state is mentioned
A9: RA-08 | B9: Reports & Accounts | C9: Combined Filters | D9: Verify multiple simultaneous filters apply AND logic correctly | E9: Report data seeded | F9: 1. Apply Level + Sector + Year filters together 2. Inspect results | G9: level=States, sector=Health, year=2025 | H9: Only reports matching all three criteria simultaneously are returned | I9: High | J9: Medium | K9: Functional | L9: Y | M9: Executed | N9: Pass
A10: RA-09 | B10: Reports & Accounts | C10: Sort Order | D10: Verify all sort options reorder results correctly | E10: Report data seeded | F10: 1. Apply each sort option in turn: newest, oldest, title_asc, title_desc 2. Inspect ordering after each | G10: N/A | H10: Result order matches the selected sort criterion exactly | I10: Medium | J10: Low | K10: Functional | L10: Y | M10: Executed | N10: Failed | O10: Sort by year alone - fail
A11: RA-10 | B11: Reports & Accounts | C11: Pagination | D11: Verify pagination returns correct, non-duplicated records across pages | E11: More than one page of reports exists | F11: 1. Navigate to page 1, then page 2, then page 3 2. Compare record IDs across pages | G11: page=1,2,3; pageSize=9 | H11: No record appears on more than one page and no records are skipped | I11: High | J11: Medium | K11: Functional | L11: Y | M11: Executed | N11: Failed | O11: UI correction
A12: RA-11 | B12: Reports & Accounts | C12: Report Detail View | D12: Verify a report's detail data is complete and correct | E12: A known report exists | F12: 1. Open a report's detail link 2. Verify title, sector, admin_level, report_type, published_date and file_url | G12: A known report ID | H12: All fields match the source data exactly with no missing values | I12: High | J12: Medium | K12: Functional | L12: Y | M12: Executed | N12: Failed | O12: #VALUE! | P12: Dates are mismatched
A13: RA-12 | B13: Reports & Accounts | C13: Report File Download | D13: Verify downloading a report file works correctly | E13: A report with a file_url exists | F13: 1. Click the report's file/download link 2. Verify the downloaded file | G13: A known report with an attached PDF | H13: The correct document downloads and opens without corruption | I13: High | J13: Medium | K13: Functional | L13: N | M13: Executed | N13: Failed | O13: #VALUE! | P13: Routes to D7 and tells error
A14: RA-13 | B14: Reports & Accounts | C14: No Results State | D14: Verify a clear message displays when search/filter criteria return zero results | E14: Report data seeded | F14: 1. Enter a search term/filter combination guaranteed to match nothing 2. Observe the results area | G14: A nonsense keyword, e.g. 'zzzznoresults' | H14: A clear 'no results found' message displays; page does not error or show a blank area | I14: Medium | J14: Medium | K14: Functional | L14: Y | M14: Executed | N14: Pass
A15: RA-14 | B15: Reports & Accounts | C15: Filters Sidebar UI | D15: Verify the filters sidebar expands/collapses and reflects active selections | E15: On Reports page | F15: 1. Toggle the filters sidebar open/closed 2. Apply a filter 3. Observe sidebar state | G15: N/A | H15: Sidebar toggles smoothly and visually indicates which filters are currently active | I15: Medium | J15: Low | K15: UI/UX | L15: N | M15: Executed | N15: Failed | O15: No side bar Collapse
A16: RA-15 | B16: Reports & Accounts | C16: State Accounts Listing | D16: Verify State Accounts section lists paginated records correctly | E16: State accounts data seeded | F16: 1. Navigate to Accounts > State Accounts 2. Inspect list and pagination | G16: N/A | H16: Records display correctly with working pagination matching /api/state-accounts | I16: High | J16: Medium | K16: Functional | L16: Y | M16: Executed | N16: Pass
A17: RA-16 | B17: Reports & Accounts | C17: Combined Accounts (CFRA) | D17: Verify Combined Accounts section lists and details records correctly | E17: Combined accounts data seeded | F17: 1. Navigate to Accounts > Combined Accounts 2. Open a record's detail view | G17: N/A | H17: List and detail view match /api/combined-accounts data | I17: Medium | J17: Medium | K17: Functional | L17: Y | M17: Executed | N17: Failed | O17: No data in combined accounts
A18: RA-17 | B18: Reports & Accounts | C18: Appropriation Accounts | D18: Verify Appropriation Accounts display correctly for a selected state | E18: A state with appropriation account data exists | F18: 1. Navigate to a state's Appropriation Accounts view 2. Inspect displayed data | G18: A known state | H18: Appropriation account figures display correctly and match source data | I18: Medium | J18: Medium | K18: Functional | L18: N | M18: Executed | N18: Failed | O18: Pdf could not be downloaded routes to D7
A19: RA-18 | B19: Reports & Accounts | C19: Performance with Large Dataset | D19: Verify Reports search/filter/pagination remains responsive against ~10,000 records | E19: Full seed dataset (local_reports.json) loaded | F19: 1. Perform a filtered search across the full dataset 2. Measure response time 3. Repeat for pagination through later pages | G19: Full ~10,000-record dataset | H19: Responses return within an acceptable threshold (e.g., <2-3s) with no timeout or UI freeze | I19: High | J19: High | K19: Performance | L19: N | M19: Not Executed
A20: RA-19 | B20: Reports & Accounts | C20: Report Detail – Back Navigation | D20: Verify returning from a report detail page keeps the applied filters and page | E20: Report data seeded | F20: 1. Apply filters (e.g. Type = Performance, Year = 2023) and go to page 2 2. Open a report 3. Click Back / the breadcrumb | G20: type=Performance, year=2023, page=2 | H20: Listing returns with the same filters, sort and page number applied | I20: Medium | J20: Medium | K20: Functional | L20: Y | M20: Executed | N20: Failed | O20: When selected the breadcrumb, the filters got erased
A21: RA-20 | B21: Reports & Accounts | C21: Report Detail – Invalid ID (UI) | D21: Verify the report detail page handles a non-existent ID gracefully | E21: Public site accessible | F21: 1. Open the report detail URL with a non-existent ID | G21: ID: 99999999 | H21: A friendly 'Report not found' / 404 page displays inside the site layout | I21: Medium | J21: Medium | K21: Functional | L21: Y | M21: Executed | N21: Pass
A22: RA-21 | B22: Reports & Accounts | C22: Report Detail – Hindi | D22: Verify the report detail page shows Hindi content under /hi | E22: A report with Hindi title/overview exists | F22: 1. Open the report detail under /hi | G22: A bilingual report | H22: Hindi title and overview display; the Hindi PDF is offered where available | I22: Medium | J22: Medium | K22: Localization | L22: N | M22: Executed | N22: Pass

Sheet AF - Admin - File Upload
A1: Test Case ID | B1: Module | C1: Feature / Component | D1: Test Scenario | E1: Preconditions | F1: Test Steps | G1: Test Data | H1: Expected Result | I1: Priority | J1: Severity | K1: Test Type | L1: Automation Candidate | M1: Status | N1: Actual Result | O1: Comments
A2: AF-01 | B2: Admin - File Upload | C2: Valid Image Upload | D2: Verify a valid image uploads and displays correctly | E2: Admin logged in, on a form with an image field | F2: 1. Select a valid PNG/JPG file 2. Upload 3. Save the record | G2: A valid PNG/JPG file <5MB | H2: File saves under public/admin-uploads/images and displays correctly on the record | I2: High | J2: Medium | K2: Functional | L2: Y | M2: Executed | N2: PASS | O2: Test banner “AF 01 test” created on the testing site and saved as Inactive. Image upload worked and the banner is not live.
A3: AF-02 | B3: Admin - File Upload | C3: Valid Document Upload | D3: Verify a valid document uploads and its link works | E3: Admin logged in, on a form with a file field | F3: 1. Select a valid PDF/DOCX/XLSX/ZIP file 2. Upload 3. Save the record 4. Open the resulting link | G3: A valid PDF file | H3: File saves under public/admin-uploads/uploads and the download link works correctly | I3: High | J3: Medium | K3: Functional | L3: Y | M3: Executed | N3: PASS | O3: Test PDF uploaded and saved as a link on Inactive circular “AF02”, hidden from the public site.
A4: AF-03 | B4: Admin - File Upload | C4: Invalid File Type Rejection | D4: Verify disallowed file types are rejected | E4: On a file upload field | F4: 1. Attempt to upload a disallowed file type (e.g., .exe) | G4: A .exe file | H4: Upload is rejected with a clear error message; no file is stored | I4: High | J4: High | K4: Security | L4: Y | M4: Executed | N4: PASS | O4: Uploading a .exe on the banner form was rejected with “Invalid file format (.exe),” and no link was saved.
A5: AF-04 | B5: Admin - File Upload | C5: Oversized File Rejection | D5: Verify files exceeding the size limit are rejected gracefully | E5: On a file upload field | F5: 1. Attempt to upload a file exceeding the configured size limit | G5: An oversized file | H5: Upload is rejected with a clear error message; application does not crash | I5: Medium | J5: Medium | K5: Functional | L5: N | M5: Executed | N5: PASS | O5: Uploading a 20 MB file was rejected with “The file is 20.0 MB; the limit is 10 MB.”
A6: AF-05 | B6: Admin - File Upload | C6: File Replace | D6: Verify replacing an existing file updates the reference correctly | E6: A record with an existing uploaded file | F6: 1. Edit the record 2. Upload a new file to replace the existing one 3. Save | G6: A new valid file | H6: The record now references the new file; the old file reference is updated/removed per design | I6: Medium | J6: Medium | K6: Functional | L6: N | M6: Executed | N6: PASS | O6: Replaced the banner image on AF 01 test and the record now shows the new image and stays Inactive.
A7: AF-06 | B7: Admin - File Upload | C7: Upload Feedback | D7: Verify the upload widget provides clear progress/success/error feedback | E7: On a file upload field | F7: 1. Upload a valid file 2. Observe progress indicator and success state 3. Repeat with an invalid file and observe error state | G7: N/A | H7: Clear, accurate feedback is shown for both success and error cases | I7: Low | J7: Low | K7: UI/UX | L7: N | M7: Executed | N7: PASS | O7: Valid PNG upload showed a preview and filled the asset URL, with no error.
A8: AF-07 | B8: Admin - File Upload | C8: Server-Side Type Enforcement | D8: Verify file type restrictions are enforced server-side, not only client-side | E8: API access available | F8: 1. Bypass the UI and send a disallowed file type directly to the upload API endpoint | G8: A disallowed file type via direct API call | H8: The API rejects the file; restriction is not solely client-side JavaScript | I8: High | J8: High | K8: Security | L8: N | M8: Not Executed | N8: FAIL | O8: Direct upload without login session returned Unauthorized; file type check pending.
A9: AF-08 | B9: Admin - File Upload | C9: File Deletion Handling | D9: Verify deleting a record with an attached file handles the file appropriately | E9: A record with an uploaded file exists | F9: 1. Delete the record 2. Check the uploads directory / file reference | G9: A disposable record with a file | H9: File is handled per design (removed or safely orphan-checked), with no broken references | I9: Medium | J9: Low | K9: Data Integrity | L9: N | M9: Executed | N9: PASS | O9: Test banner deleted without any errors
A10: AF-09 | B10: Admin - File Upload | C10: Duplicate Filename Handling | D10: Verify uploading two files with the same name does not cause unintended overwrite | E10: On a file upload field | F10: 1. Upload a file 2. Upload a second, different file with the identical filename | G10: Two different files sharing one filename | H10: Both files are stored correctly without one silently overwriting the other's data | I10: Medium | J10: Medium | K10: Functional | L10: N | M10: Executed | N10: PASS | O10: Two uploads with the same file name produced different asset links, so the first file was not overwritten.
A11: AF-10 | B11: Admin - File Upload | C11: Upload Under Slow Network | D11: Verify upload behaviour under simulated slow network conditions | E11: Network throttling available (e.g., DevTools) | F11: 1. Throttle network to a slow profile 2. Attempt to upload a moderately sized file | G11: A moderately sized valid file | H11: Upload completes with appropriate feedback, or fails gracefully with a retry/clear error rather than hanging indefinitely | I11: Low | J11: Low | K11: Performance | L11: N | M11: Executed | N11: PASS | O11: Image upload request returned HTTP 200 under 3G network throttling. The upload completed successfully and the application remained responsive.

Sheet Super admin 
A1: Test case | B1: Modules | C1: Sub sites | D1: Functionality | E1: Defect status | F1: Test status | G1: Tested by | H1: Defect Summary sheet | I1: Dev cag site vs Staging cag site
A2: TC_SuperAdmin_001 | B2: Home page | C2: Banners | D2: Add new Existing | E2: Pass | F2: Works | G2: Sivasri
A3: TC_SuperAdmin_002 | D3: Search keyword | E3: Pass | F3: Works | G3: Sivasri
A4: TC_SuperAdmin_003 | D4: Filter Options | E4: Pass | F4: Works | G4: Sivasri
A5: TC_SuperAdmin_004 | D5: Go & Reset | E5: Pass | F5: Works | G5: Sivasri
A6: TC_SuperAdmin_005 | D6: Page Entry | E6: Pass | F6: Works | G6: Sivasri
A7: TC_SuperAdmin_006 | D7: Edit | E7: Pass | F7: Works | G7: Sivasri
A8: TC_SuperAdmin_007 | D8: Delete | E8: Pass | F8: Works | G8: Sivasri
A9: TC_SuperAdmin_008 | D9: DB Validation
A10: TC_SuperAdmin_009 | D10: View | E10: Pass | F10: Works | G10: Sivasri
A11: TC_SuperAdmin_010 | C11: Quick Links | D11: Add new Existing | E11: Pass | F11: Works | G11: Sivasri
A12: TC_SuperAdmin_011 | D12: Live edit | E12: Pass | F12: Works | G12: Sivasri
A13: TC_SuperAdmin_012 | D13: Edit | E13: Pass | F13: Works | G13: Sivasri
A14: TC_SuperAdmin_013 | D14: Delete | E14: Pass | F14: Works | G14: Sivasri
A15: TC_SuperAdmin_014 | D15: DB Validation
A16: TC_SuperAdmin_015 | D16: View | E16: Pass | F16: Works | G16: Sivasri
A17: TC_SuperAdmin_016 | C17: Most Viewed Cards | D17: Add new Existing | E17: Fail | F17: Not Working | G17: Sivasri
A18: TC_SuperAdmin_017 | D18: Live edit | E18: Pass | F18: Works | G18: Sivasri
A19: TC_SuperAdmin_018 | D19: Edit | E19: Pass | F19: Works | G19: Sivasri
A20: TC_SuperAdmin_019 | D20: Delete | E20: Pass | F20: Works | G20: Sivasri
A21: TC_SuperAdmin_020 | D21: DB Validation
A22: TC_SuperAdmin_021 | D22: View | E22: Pass | F22: Works | G22: Sivasri
A23: TC_SuperAdmin_022 | C23: Who we are | D23: Add new Existing | E23: Fail | F23: Not Working | G23: Sivasri
A24: TC_SuperAdmin_023 | D24: Live edit | E24: Fail | F24: Not Working | G24: Sivasri
A25: TC_SuperAdmin_024 | D25: Edit narrative | E25: Pass | F25: Works | G25: Sivasri
A26: TC_SuperAdmin_025 | D26: Modify | E26: Pass | F26: Works | G26: Sivasri
A27: TC_SuperAdmin_026 | D27: Edit | E27: Fail | F27: Not Working | G27: Sivasri
A28: TC_SuperAdmin_027 | D28: Delete | E28: Pass | F28: Works | G28: Sivasri
A29: TC_SuperAdmin_028 | D29: DB Validation
A30: TC_SuperAdmin_029 | D30: View | E30: Pass | F30: Works | G30: Sivasri
A31: TC_SuperAdmin_030 | C31: Statistics | D31: Add new Existing | E31: Pass | F31: Works | G31: Sivasri
A32: TC_SuperAdmin_031 | D32: Live edit | E32: Pass | F32: Works | G32: Sivasri
A33: TC_SuperAdmin_032 | D33: Edit | E33: Pass | F33: Works | G33: Sivasri
A34: TC_SuperAdmin_033 | D34: Delete | E34: Pass | F34: Works | G34: Sivasri
A35: TC_SuperAdmin_034 | D35: DB Validation
A36: TC_SuperAdmin_035 | D36: View | E36: Pass | F36: Works | G36: Sivasri
A37: TC_SuperAdmin_036 | C37: CAG Message | D37: Save Message | E37: Pass | F37: Works | G37: Sivasri
A38: TC_SuperAdmin_037 | D38: Live edit | E38: Pass | F38: Works | G38: Sivasri
A39: TC_SuperAdmin_038 | D39: DB Validation
A40: TC_SuperAdmin_039 | C40: News & Events | D40: Add new Existing | E40: Fail | F40: Not Working | G40: Sivasri
...

Sheet GR - Global Relations
A1: Test Case ID | B1: Module | C1: Feature / Component | D1: Test Scenario | E1: Preconditions | F1: Test Steps | G1: Test Data | H1: Expected Result | I1: Priority | J1: Severity | K1: Test Type | L1: Automation Candidate | M1: Status | N1: Actual Result | O1: Comments
A2: GR-01 | B2: Global Relations | C2: Admin CMS - List Screen | D2: Verify the Global Relations admin list screen matches the Figma list/CRUD pattern | E2: Admin logged in | F2: 1. Navigate to Main CAG Website > Global Relations 2. Verify the Search & Filter panel (Search For, Website, Status), Sort By/Rows-per-page, and the table columns (ID, Title, Language, Status, Created, Modified, Actions) | G2: Figma Global Relations frame | H2: List screen fields, table columns and controls match Figma exactly, or the screen is confirmed not-yet-shipped and logged as a tracked build gap | I2: High | J2: Medium | K2: Design Parity | L2: N | M2: Fail | N2: Couldn’t compare with Figma since it’s not available. The admin list has Domain and Status filters, no Language column, couldn’t find Sort By or Rows per page. | O2: Figma not available, so layout couldn’t be checked
A3: GR-02 | B3: Global Relations | C3: Admin CMS - Add New Entry | D3: Verify a new Global Relations entry (e.g., an international engagement, MOU or delegation record) can be created | E3: Admin logged in, on the Global Relations list | F3: 1. Click "+ Add New" 2. Fill all mandatory fields 3. Save | G3: Valid Global Relations entry data | H3: Entry is saved and appears in the list immediately | I3: High | J3: Medium | K3: Functional | L3: Y | M3: Fail | N3: No Add or New button on any Global Relations tab, only Live Editor. | O3: No Add or New button found on International Bodies, Bilateral Relations, Audit Engagements, or Relations Wing. Only Live Editor is available.
